<?xml version="1.0"?>
<robot name="drivebot">

  <link name="chassis">
    <visual>
      <geometry>
        <box size="1 0.5 0.25"/>
      </geometry>
      <origin rpy="0 0 0" xyz="0 0 0"/>
    </visual>
    <collision>
      <geometry>
        <box size="1 0.5 0.25"/>
      </geometry>
      <origin rpy="0 0 0" xyz="0 0 0"/>
    </collision>
    <inertial>
      <mass value="2"/>
      <inertia ixx="0.0104" ixy="0.0" ixz="0.0" iyy="0.04166" iyz="0.0" izz="0.05208"/>
      <origin rpy="0 0 0" xyz="0 0 0"/>
    </inertial>
  </link>  

  <link name="right_wheel">
    <visual>
      <geometry>
        <cylinder length="0.2" radius="0.5"/>
      </geometry>
      <origin rpy="1.57075 0 0" xyz="0 -0.1 0"/>
    </visual>
    <collision>
      <geometry>
        <cylinder length="0.2" radius="0.5"/>
      </geometry>
      <origin rpy="1.57075 0 0" xyz="0 -0.1 0"/>
    </collision>
    <inertial>
      <mass value="0.25"/>
      <inertia ixx="0.047375" ixy="0.0" ixz="0.0" iyy="0.011844" iyz="0.0" izz="0.0078125"/>
      <origin rpy="1.57075 0 0" xyz="0 -0.1 0"/>
    </inertial>
  </link>

  <link name="left_wheel">
    <visual>
      <geometry>
        <cylinder length="0.2" radius="0.5"/>
      </geometry>
      <origin rpy="1.57075 0 0" xyz="0 0.1 0"/>
    </visual>
    <collision>
      <geometry>
        <cylinder length="0.2" radius="0.5"/>
      </geometry>
      <origin rpy="1.57075 0 0" xyz="0 0.1 0"/>
    </collision>
    <inertial>
      <mass value="0.25"/>
      <inertia ixx="0.047375" ixy="0.0" ixz="0.0" iyy="0.011844" iyz="0.0" izz="0.0078125"/>
      <origin rpy="1.57075 0 0" xyz="0 0.1 0"/>
    </inertial>
  </link>

  <link name="rear_wheel_support">
    <visual>
      <geometry>
        <cylinder length="0.26" radius="0.05"/>
      </geometry>
      <origin rpy="0 0 0" xyz="0 0 -0.13"/>      
    </visual>
    <collision>
      <geometry>
        <cylinder length="0.26" radius="0.05"/>
      </geometry>
      <origin rpy="0 0 0" xyz="0 0 -0.13"/>      
    </collision>
    <inertial>
      <mass value="0.01"/>
      <inertia ixx="0.00003958" ixy="0.0" ixz="0.0" iyy="0.00003958" iyz="0.0" izz="0.0000125"/>
      <origin rpy="0 0 0" xyz="0 0 -0.13"/>       
    </inertial>
  </link>

  <link name="rear_wheel">
    <visual>
      <geometry>
        <sphere radius="0.24"/>
      </geometry>
      <origin rpy="0 0 0" xyz="0 0 0"/>
    </visual>
    <collision>
      <geometry>
        <sphere radius="0.20"/>
      </geometry>
      <origin rpy="0 0 0" xyz="0 0 0"/>      
    </collision>
    <inertial>
      <mass value="0.30"/>
      <inertia ixx="0.005" ixy="0.0" ixz="0.0" iyy="0.005" iyz="0.0" izz="0.005"/>
      <origin rpy="0 0 0" xyz="0 0 0"/>
    </inertial> 
  </link>

  <link name="camera_link">
    <visual>
      <geometry>
        <box size="0.1016 0.1016 0.1016"/>
      </geometry>
      <origin rpy="0 0 0" xyz="0 0 0.0508"/>
    </visual>
    <collision>
      <geometry>
        <box size="0.1016 0.1016 0.1016"/>
      </geometry>
      <origin rpy="0 0 0" xyz="0 0 0.0508"/>
    </collision>
    <inertial>
      <mass value="0.113398093"/>
      <inertia ixx="0.0001950931" ixy="0.0" ixz="0.0" iyy="0.0001950931" iyz="0.0" izz="0.0001950931"/>
      <origin rpy="0 0 0" xyz="0 0 0.0508"/>
    </inertial>
  </link>  


  <joint name="chassis_to_right_wheel" type="continuous">
    <parent link="chassis"/>
    <child link="left_wheel"/>
    <origin rpy="0 0 0" xyz="0.45 0.25 -0.125"/>
    <axis xyz="0 1 0"/>
    <limit effort="100" velocity="100"/>
    <dynamics damping="0.0001"/>
  </joint>

  <joint name="chassis_to_left_wheel" type="continuous">
    <parent link="chassis"/>
    <child link="right_wheel"/>
    <origin rpy="0 0 0" xyz="0.45 -0.25 -0.125"/>
    <axis xyz="0 1 0"/>
    <limit effort="100" velocity="100"/>
    <dynamics damping="0.0001"/>
  </joint>

  <joint name="chassis_to_rear_wheel_support" type="continuous">
    <parent link="chassis"/>
    <child link="rear_wheel_support"/>
    <origin rpy="0 0 0" xyz="-0.45 0 -0.125"/>
    <axis xyz="0 0 1"/>
    <limit effort="100" velocity="100"/>
    <dynamics damping="0.0001"/>
  </joint>

  <joint name="rear_wheel_support_to_rear_wheel" type="continuous">
    <parent link="rear_wheel_support"/>
    <child link="rear_wheel"/>
    <origin rpy="0 0 0" xyz="-0.05 0 -0.26"/>
    <axis xyz="0 1 0"/>
    <limit effort="100" velocity="100"/>
    <dynamics damping="0.01"/>
  </joint>

  <joint name="chassis_to_camera_link" type="fixed">
    <parent link="chassis"/>
    <child link="camera_link"/>
    <origin rpy="0 0 0" xyz="0.49 0 0.125"/>
  </joint>

  <gazebo reference="chassis">
    <material>Gazebo/Black</material>
  </gazebo>

  <gazebo reference="right_wheel">
    <mu1>1.0</mu1>
    <mu2>1.0</mu2>
    <kp>10000000.0</kp>
    <kd>1.0</kd>
    <material>Gazebo/Orange</material>
  </gazebo>

  <gazebo reference="left_wheel">
    <mu1>1.0</mu1>
    <mu2>1.0</mu2>
    <kp>10000000.0</kp>
    <kd>1.0</kd>
    <material>Gazebo/Orange</material>
  </gazebo>

  <gazebo reference="rear_wheel_support">
    <material>Gazebo/White</material>
  </gazebo>

  <gazebo reference="rear_wheel">
    <mu1>1.0</mu1>
    <mu2>1.0</mu2>
    <kp>10000000.0</kp>
    <kd>1.0</kd>
    <material>Gazebo/Orange</material>
  </gazebo>

  <gazebo reference="camera_link">
    <material>Gazebo/Red</material>
    <sensor type="camera" name="camera1">
      <update_rate>30.0</update_rate>
      <camera name="head">
        <horizontal_fov>1.3962634</horizontal_fov>
        <image>
          <width>800</width>
          <height>800</height>
          <format>R8G8B8</format>
        </image>
        <clip>
          <near>0.02</near>
          <far>300</far>
        </clip>
        <noise>
          <type>gaussian</type>
          <!-- Noise is sampled independently per pixel on each frame.
               That pixel's noise value is added to each of its color
               channels, which at that point lie in the range [0,1]. -->
          <mean>0.0</mean>
          <stddev>0.007</stddev>
        </noise>
      </camera>
      <plugin name="camera_controller" filename="libgazebo_ros_camera.so">
        <alwaysOn>true</alwaysOn>
        <updateRate>0.0</updateRate>
        <cameraName>drivebot/camera1</cameraName>
        <imageTopicName>image_raw</imageTopicName>
        <cameraInfoTopicName>camera_info</cameraInfoTopicName>
        <frameName>camera_link</frameName>
        <hackBaseline>0.07</hackBaseline>
        <distortionK1>0.0</distortionK1>
        <distortionK2>0.0</distortionK2>
        <distortionK3>0.0</distortionK3>
        <distortionT1>0.0</distortionT1>
        <distortionT2>0.0</distortionT2>
      </plugin>
    </sensor>
  </gazebo>

  <gazebo>
    <plugin name="front_wheel_differential_drive_controller" filename="libgazebo_ros_diff_drive.so">
      <legacyMode>true</legacyMode>
      <alwaysOn>true</alwaysOn>
      <updateRate>100</updateRate>
      <leftJoint>chassis_to_left_wheel</leftJoint>
      <rightJoint>chassis_to_right_wheel</rightJoint>
      <wheelSeparation>0.5</wheelSeparation>
      <wheelDiameter>0.25</wheelDiameter>
      <torque>30</torque>
      <commandTopic>cmd_vel</commandTopic>
      <odometryTopic>odom</odometryTopic>
      <odometryFrame>odom</odometryFrame>
      <robotBaseFrame>chassis</robotBaseFrame>
    </plugin>
  </gazebo>

</robot>
